Workbook

Sheet Подъезд 1
A1: Этаж | B1: # квартиры | C1: каддастровый номер | D1: Площадь | E1: Электронно | F1: Бланк | G1: ФИО | H1: камеры | I1: Телефон
A2: 1 | B2: 1 | C2: 91:02:001013:7108 | I2: 7978-898-34-17
A3: 1 | B3: 2 | C3: 91:02:001013:7109 | D3: 42 | F3: 1 | G3: Царков Сергей Александрович
A4: 1 | B4: 3 | C4: 91:02:001013:7110 | D4: 59 | F4: 1 | G4: Царков Сергей Александрович
A5: 1 | B5: 4 | C5: 91:02:001013:7111 | D5: 41.3 | F5: 1 | G5: ООО "Опт индустрия" | I5: 7978-721-11-49
A6: 1 | B6: 5 | C6: 91:02:001013:7112 | D6: 61.8 | F6: 1 | G6: Чижов Алексей Николаевич
A7: 1 | B7: 6 | C7: 91:02:001013:7113 | D7: 97.6 | E7: 1 | G7: Козыкина | I7: 9182495932
A8: 1 | B8: 7 | C8: 91:02:001013:7114-91/001/2020-3 от 17.09.2020 | D8: 59.1 | F8: 1 | G8: Лещенко | I8: 7978 56 82891
A9: 1 | B9: 8 | C9: 91:02:001013:7115 | D9: 51.9 | F9: 1 | I9: 7978-844-55-98
A10: 2 | B10: 9 | C10: 91:02:001013:7116
A11: 2 | B11: 10 | C11: 91:02:001013:7117 | D11: 41.9 | F11: 1 | G11: Хорошилова Любовь Иванова
A12: 2 | B12: 11 | C12: 91:02:001013:7118 | D12: 58.5 | F12: 1 | I12: 9789177815, 7978-615-87-97
A13: 2 | B13: 12 | C13: 91:02:001013:7119 | I13: 7918-581-75-36
A14: 2 | B14: 13 | C14: 91:02:001013:7120 | D14: 61.2 | F14: 1 | I14: 8978-179-13-71
A15: 2 | B15: 14 | C15: 91:02:001013:7121
A16: 2 | B16: 15 | C16: 91:02:001013:7122 | D16: 0 | I16: 79787097421
A17: 2 | B17: 16 | C17: 91:02:001013:7123 | F17: 1 | G17: Мамонова Ольга Болисовна
A18: 3 | B18: 17 | C18: 91:02:001013:7124 | I18: 79787500462
A19: 3 | B19: 18 | C19: 91:02:001013:7125 | F19: 0 | G19: без паспорта | I19: 8978-749-38-89
A20: 3 | B20: 19 | C20: 91:02:001013:7126 | D20: 58.7 | F20: 1 | I20: 79113061631
A21: 3 | B21: 20 | C21: 91:02:001013:7127 | D21: 0 | F21: 1 | I21: 79781134312, 7978-051-72-24
A22: 3 | B22: 21 | C22: 91:02:001013:7128 | D22: 0 | F22: 1 | I22: 79787420875
A23: 3 | B23: 22 | C23: 91:02:001013:7129
A24: 3 | B24: 23 | C24: 91:02:001013:7130 | D24: 58.7 | F24: 1 | I24: 8953-308-17-27
A25: 3 | B25: 24 | C25: 91:02:001013:7131 | G25: Инна Манковская + 205 | I25: =+79049884583 -> 79049884583
A26: 4 | B26: 25 | C26: 91:02:001013:7132 | D26: 31.8 | F26: 1 | I26: 8978-831-50-91
A27: 4 | B27: 26 | C27: 91:02:001013:7133 | D27: 41.2 | F27: 1 | G27: Оксана офис 32 (парихмахерская около 1ого подъезда) | I27: 8978-795-99-92
A28: 4 | B28: 27 | C28: 91:02:001013:7134 | D28: 58.6 | F28: 1 | G28: Злобин
A29: 4 | B29: 28 | C29: 91:02:001013:7135 | D29: 41 | F29: 1 | I29: 7978-070-09-11
A30: 4 | B30: 29 | C30: 91:02:001013:7136 | D30: 61.2 | F30: 1 | G30: Виктор Головенский | I30: 7978 898 3417
A31: 4 | B31: 30 | C31: 91:02:001013:7137 | D31: 97.2 | F31: 1 | I31: 7989-293-67-14
A32: 4 | B32: 31 | C32: 91:02:001013:7138 | D32: 58.9 | E32: 1 | I32: 8919-889-54-46
A33: 4 | B33: 32 | C33: 91:02:001013:7139 | D33: 51.4 | E33: 1 | I33: 7978-712-55-45
A34: 5 | B34: 33 | C34: 91:02:001013:7140 | E34: 1 | I34: 7983451366
A35: 5 | B35: 34 | C35: 91:02:001013:7141 | I35: =+79787152636, 7978-872-27-17
A36: 5 | B36: 35 | C36: 91:02:001013:7142
A37: 5 | B37: 36 | C37: 91:02:001013:7143 | D37: 41.4 | E37: 1
A38: 5 | B38: 37 | C38: 91:02:001013:7144 | E38: 0 | I38: =+79788664720, 7978-866-47-20, 7978-091-54-59
A39: 5 | B39: 38 | C39: 91:02:001013:7145 | D39: 97.4 | E39: 1 | G39: Ирина Сергеенкова | I39: 7978-749-04-33
A40: 5 | B40: 39 | C40: 91:02:001013:7146 | D40: 59.2 | F40: 1 | I40: 7978-801-23-72
...

Sheet Подъезд 2
A1: Этаж | B1: # квартиры | C1: каддастровый номер | D1: Квадратура | E1: Электронно | F1: Бланк | G1: ФИО | H1: Камеры | I1: Телефон
A2: 1 | B2: 81 | C2: 91:02:001013:7189 | D2: 37.5 | F2: 1 | I2: 79781467629
A3: 1 | B3: 82 | C3: 91:02:001013:7190 | G3: нет паспорта | I3: 7978-842-51-59
A4: 1 | B4: 83 | C4: 91:02:001013:7191 | I4: =79787493193 -> 79787493193
A5: 1 | B5: 84 | C5: 91:02:001013:7192 | F5: 0 | I5: 7978-749-41-93
A6: 1 | B6: 85 | C6: 91:02:001013:7193 | F6: 0 | I6: =79787494192 -> 79787494192
A7: 1 | B7: 86 | C7: 91:02:001013:7194 | I7: 79104179111
A8: 1 | B8: 87 | C8: 91:02:001013:7195 | D8: 38.4 | F8: 1 | I8: 7978-535-97-08
A9: 1 | B9: 88 | C9: 91:02:001013:7196 | I9: 7916-530-68-57
A10: 2 | B10: 89 | C10: 91:02:001013:7197 | F10: 0 | I10: 8978-032-34-07
A11: 2 | B11: 90 | C11: 91:02:001013:7198 | D11: 38.2 | F11: 1
A12: 2 | B12: 91 | C12: 91:02:001013:7199 | F12: 0 | I12: 8978-760-92-66
A13: 2 | B13: 92 | C13: 91:02:001013:7200 | D13: 57.9 | F13: 1
A14: 2 | B14: 93 | C14: 91:02:001013:7201 | D14: 58 | F14: 1 | G14: Кореяк | I14: 8978-748-65-21
A15: 2 | B15: 94 | C15: 91:02:001013:7202 | F15: 0
A16: 2 | B16: 95 | C16: 91:02:001013:7203 | D16: 38.4 | E16: 1
A17: 2 | B17: 96 | C17: 91:02:001013:7204 | I17: 8988-414-71-50
A18: 3 | B18: 97 | C18: 91:02:001013:7205 | D18: 36.8 | F18: 1 | I18: 8978-562-58-01
A19: 3 | B19: 98 | C19: 91:02:001013:7206 | F19: 0
A20: 3 | B20: 99 | C20: 91:02:001013:7207 | I20: 7978-822-84-96
A21: 3 | B21: 100 | C21: 91:02:001013:7208 | D21: 56.1 | F21: 1 | G21: Елена Богданова | I21: 7 978 817 5764
A22: 3 | B22: 101 | C22: 91:02:001013:7209 | D22: 55.9 | F22: 1 | I22: 7978-817-57-64
A23: 3 | B23: 102 | C23: 91:02:001013:7210 | D23: 36 | F23: 1
A24: 3 | B24: 103 | C24: 91:02:001013:7211 | I24: 8978-765-58-05
A25: 3 | B25: 104 | C25: 91:02:001013:7212 | D25: 39.7 | F25: 1
A26: 4 | B26: 105 | C26: 91:02:001013:7213 | D26: 37.2 | F26: 1 | I26: 7978-704-02-04
A27: 4 | B27: 106 | C27: 91:02:001013:7214 | F27: 0
A28: 4 | B28: 107 | C28: 91:02:001013:7215 | D28: 53.7 | F28: 1
A29: 4 | B29: 108 | C29: 91:02:001013:7216 | D29: 55.6 | F29: 1 | I29: 7984-136-27-33
A30: 4 | B30: 109 | C30: 91:02:001013:7217 | D30: 55.7 | F30: 1 | I30: 7978-739-04-44
A31: 4 | B31: 110 | C31: 91:02:001013:7218 | F31: 0 | I31: 7978-890-73-15
A32: 4 | B32: 111 | C32: 91:02:001013:7219 | D32: 38 | F32: 1 | I32: 797873048-95, 7978-275-01-50
A33: 4 | B33: 112 | C33: 91:02:001013:7220 | D33: 39.8 | F33: 1
A34: 5 | B34: 113 | C34: 91:02:001013:7221 | I34: 8978-545-89-15
A35: 5 | B35: 114 | C35: 91:02:001013:7222 | G35: возможно противники без номера квартиры | I35: 7916-804-92-21
A36: 5 | B36: 115 | C36: 91:02:001013:7223 | D36: 55.1 | F36: 1
A37: 5 | B37: 116 | C37: 91:02:001013:7224 | D37: 55.8 | F37: 1 | G37: Анна | I37: 7978-063-17-01
A38: 5 | B38: 117 | C38: 91:02:001013:7225 | I38: 7978-725-42-87
A39: 5 | B39: 118 | C39: 91:02:001013:7226 | D39: 36.1 | E39: 1 | I39: 7978-570-00-87
A40: 5 | B40: 119 | C40: 91:02:001013:7227
...

Sheet Подъезд 3
A1: Этаж | B1: # квартиры | C1: каддастровый номер | D1: Квадратура | E1: Электронно | F1: Бланк | G1: ФИО | H1: Камера | I1: телефон
A2: 1 | B2: 161 | C2: 91:02:001013:7268 | D2: 40.1 | F2: 1 | I2: =+79002023500, 7917-425-00-52
A3: 1 | B3: 162 | C3: 91:02:001013:7269 | D3: 38.2 | F3: 1 | G3: Пигарева Любовь | I3: 8978-165-34-46
A4: 1 | B4: 163 | C4: 91:02:001013:7270 | D4: 36.6 | F4: 1
A5: 1 | B5: 164 | C5: 91:02:001013:7271
A6: 1 | B6: 165 | C6: 91:02:001013:7272 | D6: 58.1 | F6: 1 | G6: Пигарева | I6: 79787093496
A7: 1 | B7: 166 | C7: 91:02:001013:7273 | D7: 55.2 | F7: 1 | G7: Пигарева | I7: 7918-050-21-03
A8: 2 | B8: 167 | C8: 91:02:001013:7274 | D8: 39.8 | F8: 1 | H8: 1000 | I8: 7978-725-48-67
A9: 2 | B9: 168 | C9: 91:02:001013:7275
A10: 2 | B10: 169 | C10: 91:02:001013:7276 | D10: 36.4 | F10: 1 | H10: 1000 | I10: 7978-761-45-42
A11: 2 | B11: 170 | C11: 91:02:001013:7277 | D11: 58 | E11: 1 | H11: 1000 | I11: 7978-044-54-37
A12: 2 | B12: 171 | C12: 91:02:001013:7278 | F12: 0 | G12: Журавлёв Сергей Иванович Живут на маячной друзья | I12: 79124159332
A13: 2 | B13: 172 | C13: 91:02:001013:7279 | D13: 85 | F13: 1 | H13: 1000
A14: 2 | B14: 173 | C14: 91:02:001013:7280 | I14: 7918-159-57-56
A15: 3 | B15: 174 | C15: 91:02:001013:7281 | F15: 1 | G15: Наталья Ивановна | H15: 1000 | I15: 79787254867
A16: 3 | B16: 175 | C16: 91:02:001013:7282 | D16: 38.4 | F16: 1 | G16: Владимир Викторович | H16: 1000 | I16: 79787156281
A17: 3 | B17: 176 | C17: 91:02:001013:7283 | D17: 36.3 | F17: 1 | G17: Злобин Василий Васильевич | H17: 1000 | I17: 8978-126-85-05
A18: 3 | B18: 177 | C18: 91:02:001013:7284 | D18: 55.4 | E18: 1 | H18: 1000 | I18: 7978-455-05-75
A19: 3 | B19: 178 | C19: 91:02:001013:7285 | D19: 55.9 | F19: 1 | G19: Мария | H19: 1000 | I19: 7978-766-97-59
A20: 3 | B20: 179 | C20: 91:02:001013:7286 | D20: 84.9 | F20: =1/8 -> 0.125 | H20: 1000 | I20: 7978-682-85-82
A21: 3 | B21: 180 | C21: 91:02:001013:7287 | D21: 55.3 | F21: 1 | H21: 1000 | I21: 7978-768-37-89
A22: 4 | B22: 181 | C22: 91:02:001013:7288 | D22: 39.8 | F22: 1 | H22: 1000 | I22: 7978-873-76-23
A23: 4 | B23: 182 | C23: 91:02:001013:7289 | I23: 8978-037-35-08, 7978-215-81-12
A24: 4 | B24: 183 | C24: 91:02:001013:7290 | H24: 1000 | I24: 7978-776-85-98
A25: 4 | B25: 184 | C25: 91:02:001013:7291 | D25: 55.8 | F25: 1 | G25: Опт +195, 197, 215 | H25: 1000
A26: 4 | B26: 185 | C26: 91:02:001013:7292 | D26: 55 | F26: 1 | H26: 1000 | I26: 7978-748-79-53
A27: 4 | B27: 186 | C27: 91:02:001013:7293 | D27: 85 | E27: 0.25 | F27: 0.25 | H27: 1000 | I27: 79780445698
A28: 4 | B28: 187 | C28: 91:02:001013:7294
A29: 5 | B29: 188 | C29: 91:02:001013:7295 | I29: 7978-796-91-08
A30: 5 | B30: 189 | C30: 91:02:001013:7296 | G30: Терентьева +217 | H30: 1000 | I30: 79108235310
A31: 5 | B31: 190 | C31: 91:02:001013:7297 | D31: 36.3 | F31: 1 | G31: Злобин Василий Васильевич +27, 176 | H31: 1000 | I31: 79781268505
A32: 5 | B32: 191 | C32: 91:02:001013:7298 | D32: 55.9 | F32: 1 | I32: 7978-818-95-55
A33: 5 | B33: 192 | C33: 91:02:001013:7299 | D33: 55.8 | E33: 1 | H33: 1000 | I33: 7924-466-72-70
A34: 5 | B34: 193 | C34: 91:02:001013:7300 | D34: 0 | F34: 1 | I34: 79787975022, 7914-197-02-25
A35: 5 | B35: 194 | C35: 91:02:001013:7301 | D35: 55.3 | F35: 1 | H35: 1000 | I35: 7914-197-02-25
A36: 6 | B36: 195 | C36: 91:02:001013:7302 | D36: 40.2 | F36: 1 | G36: Опт | H36: 1000 | I36: 7916-102-66-62
A37: 6 | B37: 196 | C37: 91:02:001013:7303
A38: 6 | B38: 197 | C38: 91:02:001013:7304 | D38: 36.2 | F38: 1 | G38: Опт | H38: 1000
A39: 6 | B39: 198 | C39: 91:02:001013:7305 | D39: 55.8 | E39: 1 | H39: 1000 | I39: 7978-812-74-02
A40: 6 | B40: 199 | C40: 91:02:001013:7306 | F40: 1 | H40: 1000
...

Sheet Офисы
A1: # квартиры | B1: каддастровый номер | C1: Квадратура | D1: Голосует электронно | E1: Бланк | F1: ФИО | G1: Телефон
A2: 1
A3: 2
A4: 3
A5: 4 | C5: 28.3 | E5: 1 | F5: Руслана ИП кабзан | G5: 79787306003
A6: 5 | C6: 27.8 | E6: 1
A7: 6 | C7: 28.3 | E7: 1
A8: 7 | C8: 28.1 | E8: 1
A9: 8
A10: 9
A11: 10 | C11: 32.5 | E11: 1 | F11: ООО сердолик Пинская Ирина
A12: 11 | C12: 59.8 | E12: 1 | F12: Андрей | G12: 7 978 767-97-99
A13: 12 | C13: 32.5 | E13: 1 | F13: забрать 17 июля | G13: 7 978 767-97-99
A14: 13
A15: 14
A16: 15 | E16: 1
A17: 16 | C17: 48.9 | E17: 1 | F17: ООО сердолик Пинская Ирина
A18: 17 | C18: 35.2 | E18: 1 | F18: ООО сердолик Пинская Ирина
A19: 18 | C19: 35.1 | E19: 1 | F19: Оксана Владимировна. "Козырное бельё" | G19: 79787655805
A20: 19
A21: 20
A22: 21
A23: 22
A24: 23
A25: 24
A26: 25 | C26: 54 | E26: 1 | F26: Голд лук
A27: 26 | E27: 0
A28: 27 | F28: Anton
A29: 28 | C29: 35.1 | E29: 1 | F29: Lavanda nails Алёна Юхневич
A30: 29
A31: 30 | C31: 35.2 | E31: 1 | F31: Руслана собс. Музыка тела | G31: 79787306003
A32: 31
A33: 32 | C33: 32.3 | E33: 1
A34: 33 | C34: 93.3 | E34: 1
C35: =SUM(Офисы[Квадратура]) -> 606.4 | D35: =SUM(Офисы[Голосует электронно]) -> 0 | E35: =SUM(E2:E34) -> 16

Sheet Вопросы
A1: Номер | B1: Вопрос
A2: 1. | B2: КАМЕРЫ. Установить камеры на 0 м этаже. Установить камеры в каждый лифт. Принять в состав общедомового имущества установленные камеры. Назначить ООО "Севдомофон" организацией обслуживающей камеры в подъезде. Установить стоимость обслуживания камер в соответствии с коммерческим предложением ООО "Севдомофон". Включить в платежное поручение обслуживание камер
A3: 2. | B3: ВОДА. Установить кран в подсобное помещение в 3й подъезд 48/1 для доступа к общедомовой воде
A4: 3 | B4: ДОМОФОНЫ. Ограничить доступ во внутренний двор дома, с применением домофонного оборудования в единой сети, путем установки домофонов на все калитки.
A5: 4 | B5: ДОМОФОНЫ. Назначить "Севдомофон" организацией обслуживающей домофоны. Включить в платежное поручение выставляемый ООО «Цифровые инновации» обслуживание единой сети домофонов. Установить стоимость единой сети домофонов в соответствии с действующем тарифом ООО "Севдомофон". Договор обслуживания от ООО "Севдомофон" с тарифами прилагается к голосованию
A6: 5 | B6: ВОРОТА. Ограничение въезда транспорта во внутренний двор (кроме транспорта законных владельцев помещений, карет скорой помощи, автотранспорта МЧС и др. экстренных служб) на придомовую территорию многоквартирного дома путем установки автоматических ворот и иных средств автоматики на земельном участке многоквартирных домов ПОР 48 и ПОР 48/1.
A7: 6 | B7: ВОРОТА. Наделить ООО “Управляющая компания Стрелецкая бухта” полномочиями по согласованию установки автоматических ворот, металлического забора и иных средств автоматики на земельном участке многоквартирного дома с органами государственной власти г. Севастополя.
A8: 7 | B8: ВОРОТА. Наделить ООО “Управляющая компания Стрелецкая бухта” полномочиями на заключение договора с подрядной организацией на монтаж автоматических ворот и иных средств автоматики.
A9: 8 | B9: ВОРОТА. Наделить ООО “Управляющая компания Стрелецкая бухта” полномочиями по сбору с собственников помещений денежных средств на установку автоматических ворот и иных средств автоматики на придомовой территории ПОР 48 с подрядной организацией путем включения соответствующей графы в платежный документ, выставляемый ООО «Цифровые инновации» собственникам помещений в размере, пропорциональном занимаемой собственником площади жилого/нежилого помещения.
A10: 9 | B10: ВОРОТА. Наделить полномочиями совет дома на принятие решения об утверждении сметной стоимости автоматических ворот и иных средств автоматики, а также утверждении размера единовременной выплаты с квадратного метра
A11: 10 | B11: ВОРОТА. Включить в общедомовое имущество все ограждения, калитки и ворота с системой автоматики
A12: 11 | B12: МУСОРКА. Ограничить доступ к мусорным контейнерам расположенных по адресу ПОР 48
... A16: 15 | B16: БАННЕРЫ. Наделить полномочиями председателя совета дома и/или совет дома на согласование мест размещения рекламных конструкций и заключенных договоров. Так же председатель совета дома и/или совет дома наделяется полномочиями на согласование цены за квадратный метр. В случае многочисленных жалоб, председатель совета дома и/или совет дома наделяется полномочиями не продлевать договор на размещение рекламной конструкции.

Sheet Настройка
A1: Номер квартиры | B1: тип | G1: Типы
A2: 198 | B2: жилого помещения | G2: жилого помещения
G3: нежилого помещения
A6: Кадастровый 1 | B6: Кадастровый 2 | C6: Кадастровый 3 | D6: Кадастровый 4 | E6: Кадастровый
A7: =IFERROR(VLOOKUP(Кватрира[Номер квартиры],'Подъезд 1'!B2:C81,2,0),"") | B7: =IFERROR(VLOOKUP(Кватрира[Номер квартиры],'Подъезд 2'!B2:C81,2,0),"") | C7: =IFERROR(VLOOKUP(Кватрира[Номер квартиры],'Подъезд 3'!B2:C70,2,0),"") -> 91:02:001013:7305 | D7: =IFERROR(VLOOKUP(Кватрира[Номер квартиры],'Офисы'!B2:C34,2,0),"") | E7: =IFERROR(IFS(AND(NOT(EQ(Кадастровый[Кадастровый 1],"")),EQ(Кватрира[тип],G2)),Кадастровый[Кадастровый 1],AND(NOT(EQ(Кадастровый[Кадастровый 2],"")),EQ( Кватрира[тип],G2)),Кадастровый[Кадастровый 2],AND(NOT(EQ(Кадастровый[Кадастровый 3],"")),EQ(Кватрира[тип],G2)),Кадастровый[Кадастровый 3], AND(NOT(EQ(Кадастровый[Кадастровый 4],"")),EQ(Кватрира[тип],G3)),Кадастровый[Кадастровый 4]), "________________________________________") -> 91:02:001013:7305
A11: Квадратура 1 | B11: Квадратура 2 | C11: Квадратура 3 | D11: Квадратура 4 | E11: Квадратура
A12: =IFERROR(VLOOKUP(Кватрира[Номер квартиры],'Подъезд 1'!B2:D81,3,0),"") | B12: =IFERROR(VLOOKUP(Кватрира[Номер квартиры],'Подъезд 2'!B7:D81,3,0),"") | C12: =IFERROR(VLOOKUP(Кватрира[Номер квартиры],'Подъезд 3'!B7:D70,3,0),"") -> 55.8 | D12: =IFERROR(VLOOKUP(Кватрира[Номер квартиры],'Офисы'!B7:D34,3,0),"") | E12: =IFERROR(IFS(AND(NOT(EQ(Квадратура[Квадратура 1],"")),EQ( Кватрира[тип],G2)),Квадратура[Квадратура 1],AND(NOT(EQ(Квадратура[Квадратура 2],"")),EQ( Кватрира[тип],G2)),Квадратура[Квадратура 2],AND(NOT(EQ(Квадратура[Квадратура 3],"")),EQ(Кватрира[тип],G2)),Квадратура[Квадратура 3], AND(NOT(EQ(Квадратура[Квадратура 4],"")),EQ( Кватрира[тип],G3)),Квадратура[Квадратура 4]),"____ кв.м.,") -> 55.8
A18: Начало день | B18: Начало месяц | C18: Конец день | D18: Конец месяц
A19: 30 | B19: апреля | C19: 30 | D19: июня

Sheet Генерация
A1: РЕШЕНИЕ
A2: по вопросам повестки дня общего собрания собственников помещений многоквартирного дома, расположенного по адресу: г. Севастополь, пр-т Октябрьской революции 48 к.1
A3: ______________________________________________________________________________________________
A4: (Ф.И.О, либо наименование юр. лица - собственника помещения)
A5: ______________________________________________________________________________________________
A6: (ФИО представителя, действующего от имени собственника, при необходимости)
A7: ="- собственник "&Кватрира[тип]&" №" -> - собственник жилого помещения № | C7: =Кватрира[Номер квартиры] -> 198 | D7: общей площадью | E7: =TEXT(Квадратура[Квадратура],"0.00 кв.м.,") -> 55,80 кв.м.,
A8: находящегося (нужное подчеркнуть и соответственно указать):
A9: - в совместной собственности
A10: - индивидуальной собственности
A11: - в долевой собственности: долями ___/___
A12: ="на основании "&Кадастровый[Кадастровый] -> на основании 91:02:001013:7305 | D12: выданного | E12: «___» ____ ________
B13: (документ, подтверждающий право собственности)
A15: Документы, удостоверяющие личность физического лица, ОБЯЗАТЕЛЬНЫ для заполнения:
A16: Серия и номер паспорта ________________________ или СНИЛС № ____________________________
B17: ( 10 цифр паспорта) | D17: (11 цифр)
A18: Все данные с Решения бумажного бланка вносятся в систему ГИС ЖКХ. Без данных, удостоверяющих личность, бланк невозможно зарегистрировать в системе (кроме юридических лиц).
A19: Для организаций: ИНН _____________________, ОГРН _______________________________
A21: Форма проведения общего собрания: заочная форма с использованием системы ГИС ЖКХ.
A22: Для голосования онлайн:
A24: ="Продолжительность голосования в системе ГИС ЖКХ: с «"&Даты[Начало день]&"» "&Даты[Начало месяц]&" 2025 года 00:00 по «"&Даты[Конец день]&"» "&Даты[Конец месяц]&" 2025 года 23:59. При невозможности голосования посредством ГИС ЖКХ Вы можете проголосовать путем заполнения данного письменного бланка решения." -> Продолжительность голосования в системе ГИС ЖКХ: с «30» апреля 2025 года 00:00 по «30» июня 2025 года 23:59. При невозможности голосования посредством ГИС ЖКХ Вы можете проголосовать путем заполнения данного письменного бланка решения.
A25: ="Для голосования заполненные письменные решения необходимо опустить в любой из почтовый ящиков №70, №141, №198, расположенные в лифтовом холле до «"&Даты[Конец день]&"» "&Даты[Конец месяц]&" 2025 до 23:59, по адресу: г. Севастополь, пр-т Октябрьской революции 48 к.1." -> Для голосования заполненные письменные решения необходимо опустить в любой из почтовый ящиков №70, №141, №198, расположенные в лифтовом холле до «30» июня 2025 до 23:59, по адресу: г. Севастополь, пр-т Октябрьской революции 48 к.1.
A27: ВОПРОСЫ ГОЛОСОВАНИЯ:
A28: ='Вопросы'!A2 -> 1. | B28: ='Вопросы'!B2 -> КАМЕРЫ. Установить камеры на 0 м этаже. Установить камеры в каждый лифт. Принять в состав общедомового имущества установленные камеры. Назначить ООО "Севдомофон" организацией обслуживающей камеры в подъезде. Установить стоимость обслуживания камер в соответствии с коммерческим предложением ООО "Севдомофон". Включить в платежное поручение обслуживание камер
A29: Решение: | C29: ЗА | D29: ПРОТИВ | E29: ВОЗДЕРЖАЛСЯ
A32: ='Вопросы'!A3 -> 2. | B32: ='Вопросы'!B3 -> ВОДА. Установить кран в подсобное помещение в 3й подъезд 48/1 для доступа к общедомовой воде
A33: Решение: | C33: ЗА | D33: ПРОТИВ | E33: ВОЗДЕРЖАЛСЯ
A36: ='Вопросы'!A4 -> 3 | B36: ='Вопросы'!B4 -> ДОМОФОНЫ. Ограничить доступ во внутренний двор дома, с применением домофонного оборудования в единой сети, путем установки домофонов на все калитки.
A37: Решение: | C37: ЗА | D37: ПРОТИВ | E37: ВОЗДЕРЖАЛСЯ
A40: ='Вопросы'!A5 -> 4 | B40: ='Вопросы'!B5 -> ДОМОФОНЫ. Назначить "Севдомофон" организацией обслуживающей домофоны. Включить в платежное поручение выставляемый ООО «Цифровые инновации» обслуживание единой сети домофонов. Установить стоимость единой сети домофонов в соответствии с действующем тарифом ООО "Севдомофон". Договор обслуживания от ООО "Севдомофон" с тарифами прилагается к голосованию
A41: Решение: | C41: ЗА | D41: ПРОТИВ | E41: ВОЗДЕРЖАЛСЯ
A44: ='Вопросы'!A6 -> 5 | B44: ='Вопросы'!B6 -> ВОРОТА. Ограничение въезда транспорта во внутренний двор (кроме транспорта законных владельцев помещений, карет скорой помощи, автотранспорта МЧС и др. экстренных служб) на придомовую территорию многоквартирного дома путем установки автоматических ворот и иных средств автоматики на земельном участке многоквартирных домов ПОР 48 и ПОР 48/1.
A45: Решение: | C45: ЗА | D45: ПРОТИВ | E45: ВОЗДЕРЖАЛСЯ
A48: ='Вопросы'!A7 -> 6 | B48: ='Вопросы'!B7 -> ВОРОТА. Наделить ООО “Управляющая компания Стрелецкая бухта” полномочиями по согласованию установки автоматических ворот, металлического забора и иных средств автоматики на земельном участке многоквартирного дома с органами государственной власти г. Севастополя.
A49: Решение: | C49: ЗА | D49: ПРОТИВ | E49: ВОЗДЕРЖАЛСЯ
A52: ='Вопросы'!A8 -> 7 | B52: ='Вопросы'!B8 -> ВОРОТА. Наделить ООО “Управляющая компания Стрелецкая бухта” полномочиями на заключение договора с подрядной организацией на монтаж автоматических ворот и иных средств автоматики.
A53: Решение: | C53: ЗА | D53: ПРОТИВ | E53: ВОЗДЕРЖАЛСЯ
A56: ='Вопросы'!A9 -> 8 | B56: ='Вопросы'!B9 -> ВОРОТА. Наделить ООО “Управляющая компания Стрелецкая бухта” полномочиями по сбору с собственников помещений денежных средств на установку автоматических ворот и иных средств автоматики на придомовой территории ПОР 48 с подрядной организацией путем включения соответствующей графы в платежный документ, выставляемый ООО «Цифровые инновации» собственникам помещений в размере, пропорциональном занимаемой собственником площади жилого/нежилого помещения.
A57: Решение: | C57: ЗА | D57: ПРОТИВ | E57: ВОЗДЕРЖАЛСЯ
A60: ='Вопросы'!A10 -> 9 | B60: ='Вопросы'!B10 -> ВОРОТА. Наделить полномочиями совет дома на принятие решения об утверждении сметной стоимости автоматических ворот и иных средств автоматики, а также утверждении размера единовременной выплаты с квадратного метра
...
